#The try block will generate an error, because x is not defined:

try:
  print(x)
except:
  print("An exception occurred")

#Many Exceptions

try:
  print(x)
except NameError:
  print("Variable x is not defined")
except:
  print("Something else went wrong")